Workbook

Sheet Datos
A1: ID | B1: Tipo (detalle) | C1: Severidad | D1: Inspector | E1: Estado | F1: Categoria principal | H1: Nota: 'Categoria principal' es la clasificacion primaria usada para la Seccion 3 de Metricas (evita doble conteo cuando el Tipo detallado combina dos categorias, igual criterio que el informe PE4).
A2: D-01 | B2: Trazabilidad | C2: Mayor | D2: Lector (Kamila) | E2: Pendiente | F2: Trazabilidad
A3: D-02 | B3: Completitud | C3: Mayor | D3: Lector (Kamila) | E3: Requiere revisión adicional | F3: Completitud
A4: D-03 | B4: Consistencia diagrama-texto | C4: Menor | D4: Lector (Kamila) | E4: Pendiente | F4: Consistencia diagrama-texto o estructural
A5: D-04 | B5: Completitud | C5: (descartado) | D5: Lector (Kamila) | E5: Descartado | F5: Completitud
A6: D-05 | B6: Verificabilidad | C6: Menor | D6: Lector (Kamila) | E6: Pendiente | F6: Verificabilidad
A7: D-06 | B7: Nomenclatura / Trazabilidad | C7: Crítico | D7: Inspector 1 (Josthyn) | E7: Pendiente | F7: Trazabilidad
A8: D-07 | B8: Consistencia diagrama-texto | C8: Mayor | D8: Inspector 1 (Josthyn) | E8: Pendiente | F8: Consistencia diagrama-texto o estructural
A9: D-08 | B9: Trazabilidad | C9: Mayor | D9: Inspector 1 (Josthyn) e Inspector 2 (Carlos) | E9: Pendiente | F9: Trazabilidad
A10: D-09 | B10: Trazabilidad | C10: Mayor | D10: Inspector 1 (Josthyn) | E10: Requiere revisión adicional | F10: Trazabilidad
A11: D-10 | B11: Completitud | C11: Mayor | D11: Inspector 1 (Josthyn) | E11: Requiere revisión adicional | F11: Completitud
A12: D-11 | B12: Documentación / Estructura | C12: Menor | D12: Inspector 1 (Josthyn) | E12: Pendiente | F12: Documentacion o Estructura
A13: D-12 | B13: Completitud / Redacción | C13: Menor | D13: Inspector 1 (Josthyn) | E13: Cerrado | F13: Completitud
... A20: D-19 | B20: Completitud | C20: Mayor | D20: Inspector 2 (Carlos) | E20: Requiere revisión adicional | F20: Completitud

Sheet Metricas
A1: Metricas de Inspeccion Fagan -- ERS CarniCore
A2: Consistente con el informe PE4, Seccion 4.6. Datos crudos en la hoja 'Datos' (rango Datos!A2:E20).
A4: 1. Resumen general
A5: Defectos expuestos en la reunion (03/08, incl. 1 repeticion) | B5: 17
A6: Defectos unicos expuestos durante los bloques tematicos | B6: 16
A7: Defectos adicionales confirmados en el cierre de la misma reunion (D-17,D-18,D-19) | B7: 3
A8: Defectos unicos totales (registro final) | B8: =B6+B7 -> 19
A9: Verificacion cruzada: conteo directo en hoja Datos | B9: =COUNTA(Datos!A2:A20) -> 19
A10: Defectos aceptados | B10: =$B$9-B11 -> 17
A11: Defectos descartados | B11: =COUNTIF(Datos!E2:E20,"Descartado") -> 2
A12: Defectos cerrados de inmediato | B12: =COUNTIF(Datos!E2:E20,"Cerrado") -> 1
A14: 2. Distribucion por severidad (sobre defectos aceptados)
A15: Severidad | B15: Cantidad | C15: %
A16: Critico | B16: =COUNTIF(Datos!C2:C$20,"Cr?tico") -> 2 | C16: =B16/$B$19 -> 0.11764706
A17: Mayor | B17: =COUNTIF(Datos!C2:C$20,"Mayor") -> 10 | C17: =B17/$B$19 -> 0.58823529
A18: Menor | B18: =COUNTIF(Datos!C2:C$20,"Menor") -> 5 | C18: =B18/$B$19 -> 0.29411765
A19: Total | B19: =SUM(B16:B18) -> 17 | C19: =B19/$B$19 -> 1
A21: 3. Distribucion por tipo (sobre defectos unicos)
A22: Tipo (categoria principal) | B22: Cantidad | C22: %
A23: Trazabilidad | B23: =COUNTIF(Datos!F2:F$20,A23) -> 7 | C23: =B23/$B$30 -> 0.36842105
A24: Completitud | B24: =COUNTIF(Datos!F2:F$20,A24) -> 5 | C24: =B24/$B$30 -> 0.26315789
A25: Consistencia diagrama-texto o estructural | B25: =COUNTIF(Datos!F2:F$20,A25) -> 3 | C25: =B25/$B$30 -> 0.15789474
A26: Nomenclatura (exclusiva) | B26: =COUNTIF(Datos!F2:F$20,A26) -> 1 | C26: =B26/$B$30 -> 0.052631579
A27: Verificabilidad | B27: =COUNTIF(Datos!F2:F$20,A27) -> 1 | C27: =B27/$B$30 -> 0.052631579
A28: Documentacion o Estructura | B28: =COUNTIF(Datos!F2:F$20,A28) -> 1 | C28: =B28/$B$30 -> 0.052631579
A29: Fuera de alcance del ERS | B29: =COUNTIF(Datos!F2:F$20,A29) -> 1 | C29: =B29/$B$30 -> 0.052631579
A30: Total | B30: =SUM(B23:B29) -> 19 | C30: =B30/$B$30 -> 1
A31: Nota: clasificacion por categoria principal (defectos con doble tipo, p.ej. Nomenclatura/Trazabilidad, se cuentan bajo Trazabilidad, igual que en el informe).
A33: 4. Distribucion por inspector (hallazgos individuales antes de consolidar repetidos)
A34: Inspector | B34: Hallazgos | C34: %
A35: Lector (Kamila) | B35: =COUNTIF(Datos!D2:D$20,"*Kamila*") -> 6 | C35: =B35/$B$38 -> 0.3
A36: Inspector 1 (Josthyn) | B36: =COUNTIF(Datos!D2:D$20,"*Josthyn*") -> 8 | C36: =B36/$B$38 -> 0.4
A37: Inspector 2 (Carlos) | B37: =COUNTIF(Datos!D2:D$20,"*Carlos*") -> 6 | C37: =B37/$B$38 -> 0.3
A38: Total (incluye 1 repeticion D-08) | B38: =SUM(B35:B37) -> 20 | C38: =B38/$B$38 -> 1
A39: Nota: D-17 (Kamila) y D-18/D-19 (Carlos) surgieron en la preparacion individual y se confirmaron en el cierre de la reunion del 03/08/2026 (ver Datos y el informe, Seccion 4.3).
A41: 5. Esfuerzo (horas-persona)
A42: Actividad | B42: Horas
A43: Preparacion individual - Lector (Kamila) | B43: 3
A44: Preparacion individual - Inspector 1 (Josthyn) | B44: 4
A45: Preparacion individual - Inspector 2 (Carlos) | B45: 3.5
...
